<?xml version="1.0" ?>
<!-- =================================================================================== -->
<!-- |    This document was autogenerated by xacro from tm5-700.urdf.xacro             | -->
<!-- |    EDITING THIS FILE BY HAND IS NOT RECOMMENDED                                 | -->
<!-- =================================================================================== -->
<robot name="tm5-700">
  <gazebo reference="link_1">
    <selfCollide>true</selfCollide>
  </gazebo>
  <gazebo reference="link_2">
    <selfCollide>true</selfCollide>
  </gazebo>
  <gazebo reference="link_3">
    <selfCollide>true</selfCollide>
  </gazebo>
  <gazebo reference="link_4">
    <selfCollide>true</selfCollide>
  </gazebo>
  <gazebo reference="link_5">
    <selfCollide>true</selfCollide>
  </gazebo>
  <gazebo reference="link_6">
    <selfCollide>true</selfCollide>
  </gazebo>
  <gazebo>
    <plugin filename="libgazebo_ros_control.so" name="gazebo_ros_control">
      <robotNamespace>/</robotNamespace>
      <robotSimType>gazebo_ros_control/DefaultRobotHWSim</robotSimType>
    </plugin>
  </gazebo>
  <transmission name="trans_1">
    <type>transmission_interface/SimpleTransmission</type>
    <joint name="joint_1">
      <hardwareInterface>hardware_interface/PositionJointInterface</hardwareInterface>
    </joint>
    <actuator name="motor_1">
      <mechanicalReduction>1</mechanicalReduction>
    </actuator>
  </transmission>
  <transmission name="trans_2">
    <type>transmission_interface/SimpleTransmission</type>
    <joint name="joint_2">
      <hardwareInterface>hardware_interface/PositionJointInterface</hardwareInterface>
    </joint>
    <actuator name="motor_2">
      <mechanicalReduction>1</mechanicalReduction>
    </actuator>
  </transmission>
  <transmission name="trans_3">
    <type>transmission_interface/SimpleTransmission</type>
    <joint name="joint_3">
      <hardwareInterface>hardware_interface/PositionJointInterface</hardwareInterface>
    </joint>
    <actuator name="motor_3">
      <mechanicalReduction>1</mechanicalReduction>
    </actuator>
  </transmission>
  <transmission name="trans_4">
    <type>transmission_interface/SimpleTransmission</type>
    <joint name="joint_4">
      <hardwareInterface>hardware_interface/PositionJointInterface</hardwareInterface>
    </joint>
    <actuator name="motor_4">
      <mechanicalReduction>1</mechanicalReduction>
    </actuator>
  </transmission>
  <transmission name="trans_5">
    <type>transmission_interface/SimpleTransmission</type>
    <joint name="joint_5">
      <hardwareInterface>hardware_interface/PositionJointInterface</hardwareInterface>
    </joint>
    <actuator name="motor_5">
      <mechanicalReduction>1</mechanicalReduction>
    </actuator>
  </transmission>
  <transmission name="trans_6">
    <type>transmission_interface/SimpleTransmission</type>
    <joint name="joint_6">
      <hardwareInterface>hardware_interface/PositionJointInterface</hardwareInterface>
    </joint>
    <actuator name="motor_6">
      <mechanicalReduction>1</mechanicalReduction>
    </actuator>
  </transmission>
  <material name="none">
    <color rgba="0.0 0.0 0.0 1.0"/>
  </material>
  <material name="lightgrey">
    <color rgba="0.5 0.5 0.5 1.0"/>
  </material>
  <material name="grey">
    <color rgba="0.75 0.75 0.75 1.0"/>
  </material>
  <material name="white">
    <color rgba="0.95 0.95 0.95 1.0"/>
  </material>
  <material name="red">
    <color rgba="0.95 0.0 0.0 1.0"/>
  </material>
  <material name="orange">
    <color rgba="1.0 0.5 0.0 1.0"/>
  </material>
  <material name="yellow">
    <color rgba="1.0 1.0 0.0 1.0"/>
  </material>
  <material name="green">
    <color rgba="0.0 1.0 0.0 1.0"/>
  </material>
  <material name="blue">
    <color rgba="0.0 0.0 1.0 1.0"/>
  </material>
  <material name="indigo">
    <color rgba="0.3 0.3 0.6 1.0"/>
  </material>
  <material name="violet">
    <color rgba="0.6 0.0 1.0 1.0"/>
  </material>
  <material name="black">
    <color rgba="0.0 0.0 0.0 1.0"/>
  </material>
  <material name="darkolive">
    <color rgba="0.3 0.3 0.25 1.0"/>
  </material>
  <!--LinkDescription-->
  <link name="leftlink_0">
    <visual>
      <geometry>
        <mesh filename="/home/piatan/tmdriver_ws/src/tm_description/meshes/tm5-900/visual/tm5-base.obj"/>
      </geometry>
      <material name="none"/>
    </visual>
    <collision>
      <geometry>
        <mesh filename="/home/piatan/tmdriver_ws/src/tm_description/meshes/tm5-900/collision/tm5-base_c.stl"/>
      </geometry>
    </collision>
    <inertial>
      <mass value="1.0"/>
      <origin rpy="0.000000 0.000000 0.000000" xyz="0.000000 0.000000 0.000000"/>
      <inertia ixx="0.00110833289" ixy="0.0" ixz="0.0" iyy="0.00110833289" iyz="0.0" izz="0.0018"/>
    </inertial>
  </link>
  <joint name="leftjoint_1" type="revolute">
    <parent link="leftlink_0"/>
    <child link="leftlink_1"/>
    <origin rpy="0.000000 -0.000000 0.000000" xyz="0.000000 0.000000 0.145200"/>
    <axis xyz="0 0 1"/>
    <!--limit-->
    <limit effort="157" lower="-4.71238898038469" upper="4.71238898038469" velocity="3.141592653589793"/>
    <dynamics damping="0.0" friction="0.0"/>
  </joint>
  <link name="leftlink_1">
    <visual>
      <geometry>
        <mesh filename="/home/piatan/tmdriver_ws/src/tm_description/meshes/tm5-900/visual/tmr_400w_01.obj"/>
      </geometry>
      <material name="none"/>
    </visual>
    <collision>
      <geometry>
        <mesh filename="/home/piatan/tmdriver_ws/src/tm_description/meshes/tm5-900/collision/tmr_400w_01_c.stl"/>
      </geometry>
    </collision>
    <inertial>
      <origin rpy="0.000000 0.000000 0.000000" xyz="0.000000 0.000000 0.000000"/>
      <mass value="4.032"/>
      <inertia ixx="0.008800119" ixy="0.000000" ixz="0.000000" iyy="0.011548982" iyz="0.000000" izz="0.011970080999999999"/>
    </inertial>
  </link>
  <joint name="leftjoint_2" type="revolute">
    <parent link="leftlink_1"/>
    <child link="leftlink_2"/>
    <origin rpy="-1.570796 -1.570796 0.000000" xyz="0.000000 0.000000 0.000000"/>
    <axis xyz="0 0 1"/>
    <!--limit-->
    <limit effort="157" lower="-3.141592653589793" upper="3.141592653589793" velocity="3.141592653589793"/>
    <dynamics damping="0.0" friction="0.0"/>
  </joint>
  <link name="leftlink_2">
    <visual>
      <geometry>
        <mesh filename="/home/piatan/tmdriver_ws/src/tm_description/meshes/tm5-700/visual/tm5-700_arm1.obj"/>
      </geometry>
      <material name="none"/>
    </visual>
    <collision>
      <geometry>
        <mesh filename="/home/piatan/tmdriver_ws/src/tm_description/meshes/tm5-700/collision/tm5-700_arm1_c.stl"/>
      </geometry>
    </collision>
    <inertial>
      <origin rpy="0.000000 0.000000 0.000000" xyz="0.000000 0.000000 0.000000"/>
      <mass value="8.567"/>
      <inertia ixx="0.023552072" ixy="0.000000" ixz="0.000000" iyy="0.19825197" iyz="0.000000" izz="0.20459254"/>
    </inertial>
  </link>
  <joint name="leftjoint_3" type="revolute">
    <parent link="leftlink_2"/>
    <child link="leftlink_3"/>
    <origin rpy="0.000000 -0.000000 0.000000" xyz="0.329000 0.000000 0.000000"/>
    <axis xyz="0 0 1"/>
    <!--limit-->
    <limit effort="157" lower="-2.705260340591211" upper="2.705260340591211" velocity="3.141592653589793"/>
    <dynamics damping="0.0" friction="0.0"/>
  </joint>
  <link name="leftlink_3">
    <visual>
      <geometry>
        <mesh filename="/home/piatan/tmdriver_ws/src/tm_description/meshes/tm5-700/visual/tm5-700_arm2.obj"/>
      </geometry>
      <material name="none"/>
    </visual>
    <collision>
      <geometry>
        <mesh filename="/home/piatan/tmdriver_ws/src/tm_description/meshes/tm5-700/collision/tm5-700_arm2_c.stl"/>
      </geometry>
    </collision>
    <inertial>
      <origin rpy="0.000000 0.000000 0.000000" xyz="0.000000 0.000000 0.000000"/>
      <mass value="2.273"/>
      <inertia ixx="0.003380181" ixy="0.000000" ixz="0.000000" iyy="0.033829144" iyz="0.000000" izz="0.034328203"/>
    </inertial>
  </link>
  <joint name="leftjoint_4" type="revolute">
    <parent link="leftlink_3"/>
    <child link="leftlink_4"/>
    <origin rpy="0.000000 -0.000000 1.570796" xyz="0.311500 0.000000 -0.122300"/>
    <axis xyz="0 0 1"/>
    <!--limit-->
    <limit effort="43" lower="-3.141592653589793" upper="3.141592653589793" velocity="3.9269908169872414"/>
    <dynamics damping="0.0" friction="0.0"/>
  </joint>
  <link name="leftlink_4">
    <visual>
      <geometry>
        <mesh filename="/home/piatan/tmdriver_ws/src/tm_description/meshes/tm5-900/visual/tmr_100w_01.obj"/>
      </geometry>
      <material name="none"/>
    </visual>
    <collision>
      <geometry>
        <mesh filename="/home/piatan/tmdriver_ws/src/tm_description/meshes/tm5-900/collision/tmr_100w_01_c.stl"/>
      </geometry>
    </collision>
    <inertial>
      <origin rpy="0.000000 0.000000 0.000000" xyz="0.000000 0.000000 0.000000"/>
      <mass value="1.576"/>
      <inertia ixx="0.002058405" ixy="0.000000" ixz="0.000000" iyy="0.0025630790000000002" iyz="0.000000" izz="0.00264321"/>
    </inertial>
  </link>
  <joint name="leftjoint_5" type="revolute">
    <parent link="leftlink_4"/>
    <child link="leftlink_5"/>
    <origin rpy="1.570796 -0.000000 0.000000" xyz="0.000000 -0.106000 0.000000"/>
    <axis xyz="0 0 1"/>
    <!--limit-->
    <limit effort="43" lower="-3.141592653589793" upper="3.141592653589793" velocity="3.9269908169872414"/>
    <dynamics damping="0.0" friction="0.0"/>
  </joint>
  <link name="leftlink_5">
    <visual>
      <geometry>
        <mesh filename="/home/piatan/tmdriver_ws/src/tm_description/meshes/tm5-900/visual/tmr_100w_02.obj"/>
      </geometry>
      <material name="none"/>
    </visual>
    <collision>
      <geometry>
        <mesh filename="/home/piatan/tmdriver_ws/src/tm_description/meshes/tm5-900/collision/tmr_100w_02_c.stl"/>
      </geometry>
    </collision>
    <inertial>
      <origin rpy="0.000000 0.000000 0.000000" xyz="0.000000 0.000000 0.000000"/>
      <mass value="1.576"/>
      <inertia ixx="0.002058405" ixy="0.000000" ixz="0.000000" iyy="0.0025630790000000002" iyz="0.000000" izz="0.00264321"/>
    </inertial>
  </link>
  <joint name="leftjoint_6" type="revolute">
    <parent link="leftlink_5"/>
    <child link="leftlink_6"/>
    <origin rpy="1.570796 -0.000000 0.000000" xyz="0.000000 -0.113150 0.000000"/>
    <axis xyz="0 0 1"/>
    <!--limit-->
    <limit effort="43" lower="-4.71238898038469" upper="4.71238898038469" velocity="3.9269908169872414"/>
    <dynamics damping="0.0" friction="0.0"/>
  </joint>
  <link name="leftlink_6">
    <visual>
      <geometry>
        <mesh filename="/home/piatan/tmdriver_ws/src/tm_description/meshes/tm5-900/visual/tmr_ee.obj"/>
      </geometry>
      <material name="none"/>
    </visual>
    <collision>
      <geometry>
        <mesh filename="/home/piatan/tmdriver_ws/src/tm_description/meshes/tm5-900/collision/tmr_ee_c.stl"/>
      </geometry>
    </collision>
    <inertial>
      <origin rpy="0.000000 0.000000 0.000000" xyz="0.000000 0.000000 0.000000"/>
      <mass value="0.65"/>
      <inertia ixx="0.000774544" ixy="0.000000" ixz="0.000000" iyy="0.0013838109999999998" iyz="0.000000" izz="0.001559496"/>
    </inertial>
  </link>
  <link name="leftbase"/>
  <joint name="leftbase_fixed_joint" type="fixed">
    <parent link="leftbase"/>
    <child link="leftlink_0"/>
    <origin rpy="0.000000 0.000000 0.000000" xyz="0.000000 0.000000 0.000000"/>
  </joint>
  <link name="leftflange"/>
  <joint name="leftflange_fixed_joint" type="fixed">
    <parent link="leftlink_6"/>
    <child link="leftflange"/>
    <origin rpy="0.000000 0.000000 0.000000" xyz="0.000000 0.000000 0.000000"/>
  </joint>
  <!--LinkDescription-->
  <!--LinkDescription-->
  <link name="rightlink_0">
    <visual>
      <geometry>
        <mesh filename="/home/piatan/tmdriver_ws/src/tm_description/meshes/tm5-900/visual/tm5-base.obj"/>
      </geometry>
      <material name="none"/>
    </visual>
    <collision>
      <geometry>
        <mesh filename="/home/piatan/tmdriver_ws/src/tm_description/meshes/tm5-900/collision/tm5-base_c.stl"/>
      </geometry>
    </collision>
    <inertial>
      <mass value="1.0"/>
      <origin rpy="0.000000 0.000000 0.000000" xyz="0.000000 0.000000 0.000000"/>
      <inertia ixx="0.00110833289" ixy="0.0" ixz="0.0" iyy="0.00110833289" iyz="0.0" izz="0.0018"/>
    </inertial>
  </link>
  <joint name="rightjoint_1" type="revolute">
    <parent link="rightlink_0"/>
    <child link="rightlink_1"/>
    <origin rpy="0.000000 -0.000000 0.000000" xyz="0.000000 0.000000 0.145200"/>
    <axis xyz="0 0 1"/>
    <!--limit-->
    <limit effort="157" lower="-4.71238898038469" upper="4.71238898038469" velocity="3.141592653589793"/>
    <dynamics damping="0.0" friction="0.0"/>
  </joint>
  <link name="rightlink_1">
    <visual>
      <geometry>
        <mesh filename="/home/piatan/tmdriver_ws/src/tm_description/meshes/tm5-900/visual/tmr_400w_01.obj"/>
      </geometry>
      <material name="none"/>
    </visual>
    <collision>
      <geometry>
        <mesh filename="/home/piatan/tmdriver_ws/src/tm_description/meshes/tm5-900/collision/tmr_400w_01_c.stl"/>
      </geometry>
    </collision>
    <inertial>
      <origin rpy="0.000000 0.000000 0.000000" xyz="0.000000 0.000000 0.000000"/>
      <mass value="4.032"/>
      <inertia ixx="0.008800119" ixy="0.000000" ixz="0.000000" iyy="0.011548982" iyz="0.000000" izz="0.011970080999999999"/>
    </inertial>
  </link>
  <joint name="rightjoint_2" type="revolute">
    <parent link="rightlink_1"/>
    <child link="rightlink_2"/>
    <origin rpy="-1.570796 -1.570796 0.000000" xyz="0.000000 0.000000 0.000000"/>
    <axis xyz="0 0 1"/>
    <!--limit-->
    <limit effort="157" lower="-3.141592653589793" upper="3.141592653589793" velocity="3.141592653589793"/>
    <dynamics damping="0.0" friction="0.0"/>
  </joint>
  <link name="rightlink_2">
    <visual>
      <geometry>
        <mesh filename="/home/piatan/tmdriver_ws/src/tm_description/meshes/tm5-700/visual/tm5-700_arm1.obj"/>
      </geometry>
      <material name="none"/>
    </visual>
    <collision>
      <geometry>
        <mesh filename="/home/piatan/tmdriver_ws/src/tm_description/meshes/tm5-700/collision/tm5-700_arm1_c.stl"/>
      </geometry>
    </collision>
    <inertial>
      <origin rpy="0.000000 0.000000 0.000000" xyz="0.000000 0.000000 0.000000"/>
      <mass value="8.567"/>
      <inertia ixx="0.023552072" ixy="0.000000" ixz="0.000000" iyy="0.19825197" iyz="0.000000" izz="0.20459254"/>
    </inertial>
  </link>
  <joint name="rightjoint_3" type="revolute">
    <parent link="rightlink_2"/>
    <child link="rightlink_3"/>
    <origin rpy="0.000000 -0.000000 0.000000" xyz="0.329000 0.000000 0.000000"/>
    <axis xyz="0 0 1"/>
    <!--limit-->
    <limit effort="157" lower="-2.705260340591211" upper="2.705260340591211" velocity="3.141592653589793"/>
    <dynamics damping="0.0" friction="0.0"/>
  </joint>
  <link name="rightlink_3">
    <visual>
      <geometry>
        <mesh filename="/home/piatan/tmdriver_ws/src/tm_description/meshes/tm5-700/visual/tm5-700_arm2.obj"/>
      </geometry>
      <material name="none"/>
    </visual>
    <collision>
      <geometry>
        <mesh filename="/home/piatan/tmdriver_ws/src/tm_description/meshes/tm5-700/collision/tm5-700_arm2_c.stl"/>
      </geometry>
    </collision>
    <inertial>
      <origin rpy="0.000000 0.000000 0.000000" xyz="0.000000 0.000000 0.000000"/>
      <mass value="2.273"/>
      <inertia ixx="0.003380181" ixy="0.000000" ixz="0.000000" iyy="0.033829144" iyz="0.000000" izz="0.034328203"/>
    </inertial>
  </link>
  <joint name="rightjoint_4" type="revolute">
    <parent link="rightlink_3"/>
    <child link="rightlink_4"/>
    <origin rpy="0.000000 -0.000000 1.570796" xyz="0.311500 0.000000 -0.122300"/>
    <axis xyz="0 0 1"/>
    <!--limit-->
    <limit effort="43" lower="-3.141592653589793" upper="3.141592653589793" velocity="3.9269908169872414"/>
    <dynamics damping="0.0" friction="0.0"/>
  </joint>
  <link name="rightlink_4">
    <visual>
      <geometry>
        <mesh filename="/home/piatan/tmdriver_ws/src/tm_description/meshes/tm5-900/visual/tmr_100w_01.obj"/>
      </geometry>
      <material name="none"/>
    </visual>
    <collision>
      <geometry>
        <mesh filename="/home/piatan/tmdriver_ws/src/tm_description/meshes/tm5-900/collision/tmr_100w_01_c.stl"/>
      </geometry>
    </collision>
    <inertial>
      <origin rpy="0.000000 0.000000 0.000000" xyz="0.000000 0.000000 0.000000"/>
      <mass value="1.576"/>
      <inertia ixx="0.002058405" ixy="0.000000" ixz="0.000000" iyy="0.0025630790000000002" iyz="0.000000" izz="0.00264321"/>
    </inertial>
  </link>
  <joint name="rightjoint_5" type="revolute">
    <parent link="rightlink_4"/>
    <child link="rightlink_5"/>
    <origin rpy="1.570796 -0.000000 0.000000" xyz="0.000000 -0.106000 0.000000"/>
    <axis xyz="0 0 1"/>
    <!--limit-->
    <limit effort="43" lower="-3.141592653589793" upper="3.141592653589793" velocity="3.9269908169872414"/>
    <dynamics damping="0.0" friction="0.0"/>
  </joint>
  <link name="rightlink_5">
    <visual>
      <geometry>
        <mesh filename="/home/piatan/tmdriver_ws/src/tm_description/meshes/tm5-900/visual/tmr_100w_02.obj"/>
      </geometry>
      <material name="none"/>
    </visual>
    <collision>
      <geometry>
        <mesh filename="/home/piatan/tmdriver_ws/src/tm_description/meshes/tm5-900/collision/tmr_100w_02_c.stl"/>
      </geometry>
    </collision>
    <inertial>
      <origin rpy="0.000000 0.000000 0.000000" xyz="0.000000 0.000000 0.000000"/>
      <mass value="1.576"/>
      <inertia ixx="0.002058405" ixy="0.000000" ixz="0.000000" iyy="0.0025630790000000002" iyz="0.000000" izz="0.00264321"/>
    </inertial>
  </link>
  <joint name="rightjoint_6" type="revolute">
    <parent link="rightlink_5"/>
    <child link="rightlink_6"/>
    <origin rpy="1.570796 -0.000000 0.000000" xyz="0.000000 -0.113150 0.000000"/>
    <axis xyz="0 0 1"/>
    <!--limit-->
    <limit effort="43" lower="-4.71238898038469" upper="4.71238898038469" velocity="3.9269908169872414"/>
    <dynamics damping="0.0" friction="0.0"/>
  </joint>
  <link name="rightlink_6">
    <visual>
      <geometry>
        <mesh filename="/home/piatan/tmdriver_ws/src/tm_description/meshes/tm5-900/visual/tmr_ee.obj"/>
      </geometry>
      <material name="none"/>
    </visual>
    <collision>
      <geometry>
        <mesh filename="/home/piatan/tmdriver_ws/src/tm_description/meshes/tm5-900/collision/tmr_ee_c.stl"/>
      </geometry>
    </collision>
    <inertial>
      <origin rpy="0.000000 0.000000 0.000000" xyz="0.000000 0.000000 0.000000"/>
      <mass value="0.65"/>
      <inertia ixx="0.000774544" ixy="0.000000" ixz="0.000000" iyy="0.0013838109999999998" iyz="0.000000" izz="0.001559496"/>
    </inertial>
  </link>
  <link name="rightbase"/>
  <joint name="rightbase_fixed_joint" type="fixed">
    <parent link="rightbase"/>
    <child link="rightlink_0"/>
    <origin rpy="0.000000 0.000000 0.000000" xyz="0.000000 0.000000 0.000000"/>
  </joint>
  <link name="rightflange"/>
  <joint name="rightflange_fixed_joint" type="fixed">
    <parent link="rightlink_6"/>
    <child link="rightflange"/>
    <origin rpy="0.000000 0.000000 0.000000" xyz="0.000000 0.000000 0.000000"/>
  </joint>
  <!--LinkDescription-->
  <link name="base"/>
  <joint name="left1base_fixed_joint" type="fixed">
    <parent link="base"/>
    <child link="leftbase"/>
    <origin rpy="0.000000 0.000000 0.000000" xyz="0.000000 0.000000 0.000000"/>
  </joint>
  <joint name="right1base_fixed_joint" type="fixed">
    <parent link="base"/>
    <child link="rightbase"/>
    <origin rpy="0.000000 0.000000 0.000000" xyz="1.200000 0.000000 0.000000"/>
  </joint>
</robot>
